<?xml version="1.0"?>
<robot name="simple_humanoid">

  <link name="torso">
    <visual>
      <geometry>
        <box size="0.2 0.3 0.5"/>
      </geometry>
    </visual>
  </link>

  <link name="head">
    <visual>
      <geometry>
        <sphere radius="0.1"/>
      </geometry>
    </visual>
  </link>

  <joint name="neck" type="fixed">
    <parent link="torso"/>
    <child link="head"/>
    <origin xyz="0 0 0.3" rpy="0 0 0"/>
  </joint>

  <link name="right_upper_arm">
    <visual>
      <geometry>
        <cylinder length="0.3" radius="0.05"/>
      </geometry>
    </visual>
  </link>

  <joint name="right_shoulder" type="revolute">
    <parent link="torso"/>
    <child link="right_upper_arm"/>
    <origin xyz="-0.15 0 0.2" rpy="0 1.57 0"/>
    <axis xyz="0 1 0"/>
    <limit lower="-1.57" upper="1.57" effort="10" velocity="1"/>
  </joint>

</robot>
